2020-10-29 00:34:39: [ERROR]: django.request: Internal Server Error: / ( log.py:224)
Traceback (most recent call last):
  File "/home/tarn/.local/share/virtualenvs/temp-website-0a3D2xF1/lib/python3.8/site-packages/django/core/handlers/exception.py", line 47, in inner
    response = get_response(request)
  File "/home/tarn/.local/share/virtualenvs/temp-website-0a3D2xF1/lib/python3.8/site-packages/django/core/handlers/base.py", line 202, in _get_response
    response = response.render()
  File "/home/tarn/.local/share/virtualenvs/temp-website-0a3D2xF1/lib/python3.8/site-packages/django/template/response.py", line 105, in render
    self.content = self.rendered_content
  File "/home/tarn/.local/share/virtualenvs/temp-website-0a3D2xF1/lib/python3.8/site-packages/django/template/response.py", line 83, in rendered_content
    return template.render(context, self._request)
  File "/home/tarn/.local/share/virtualenvs/temp-website-0a3D2xF1/lib/python3.8/site-packages/django/template/backends/django.py", line 61, in render
    return self.template.render(context)
  File "/home/tarn/.local/share/virtualenvs/temp-website-0a3D2xF1/lib/python3.8/site-packages/django/template/base.py", line 170, in render
    return self._render(context)
  File "/home/tarn/.local/share/virtualenvs/temp-website-0a3D2xF1/lib/python3.8/site-packages/django/test/utils.py", line 96, in instrumented_test_render
    return self.nodelist.render(context)
  File "/home/tarn/.local/share/virtualenvs/temp-website-0a3D2xF1/lib/python3.8/site-packages/django/template/base.py", line 938, in render
    bit = node.render_annotated(context)
  File "/home/tarn/.local/share/virtualenvs/temp-website-0a3D2xF1/lib/python3.8/site-packages/django/template/base.py", line 905, in render_annotated
    return self.render(context)
  File "/home/tarn/.local/share/virtualenvs/temp-website-0a3D2xF1/lib/python3.8/site-packages/django/template/loader_tags.py", line 150, in render
    return compiled_parent._render(context)
  File "/home/tarn/.local/share/virtualenvs/temp-website-0a3D2xF1/lib/python3.8/site-packages/django/test/utils.py", line 96, in instrumented_test_render
    return self.nodelist.render(context)
  File "/home/tarn/.local/share/virtualenvs/temp-website-0a3D2xF1/lib/python3.8/site-packages/django/template/base.py", line 938, in render
    bit = node.render_annotated(context)
  File "/home/tarn/.local/share/virtualenvs/temp-website-0a3D2xF1/lib/python3.8/site-packages/django/template/base.py", line 905, in render_annotated
    return self.render(context)
  File "/home/tarn/.local/share/virtualenvs/temp-website-0a3D2xF1/lib/python3.8/site-packages/django/template/loader_tags.py", line 62, in render
    result = block.nodelist.render(context)
  File "/home/tarn/.local/share/virtualenvs/temp-website-0a3D2xF1/lib/python3.8/site-packages/django/template/base.py", line 938, in render
    bit = node.render_annotated(context)
  File "/home/tarn/.local/share/virtualenvs/temp-website-0a3D2xF1/lib/python3.8/site-packages/django/template/base.py", line 905, in render_annotated
    return self.render(context)
  File "/home/tarn/.local/share/virtualenvs/temp-website-0a3D2xF1/lib/python3.8/site-packages/django/template/defaulttags.py", line 446, in render
    url = reverse(view_name, args=args, kwargs=kwargs, current_app=current_app)
  File "/home/tarn/.local/share/virtualenvs/temp-website-0a3D2xF1/lib/python3.8/site-packages/django/urls/base.py", line 87, in reverse
    return iri_to_uri(resolver._reverse_with_prefix(view, prefix, *args, **kwargs))
  File "/home/tarn/.local/share/virtualenvs/temp-website-0a3D2xF1/lib/python3.8/site-packages/django/urls/resolvers.py", line 685, in _reverse_with_prefix
    raise NoReverseMatch(msg)
django.urls.exceptions.NoReverseMatch: Reverse for 'blog-detail' with keyword arguments '{'pk': ''}' not found. 1 pattern(s) tried: ['blog/(?P<pk>[0-9]+)/$']
